Workbook
Name Neighborhood_Main: 'Complete List_09252026'!$A$2:$L$309
Name Query_Neighborhood_List_Affiliations: #REF!

Sheet Complete List_09252026
A1: FIRST | B1: LAST | C1: NAME | D1: ORGANIZATION | E1: ADDRESS | F1: CITY | G1: STATE | H1: ZIP | I1: TELEPHONE | J1: EMAIL | K1: NOTIFICATION PREFERENCES | L1: NEIGHBORHOOD OF INTEREST
A2: Aaron | B2: Peskin | C2: =A2&" "&B2 -> Aaron Peskin | D2: - | E2: 470 Columbus Avenue, Ste. 211 | F2: San Francisco | G2: CA | H2: 94133 | I2: 415-986-7014 | J2: aaron.peskin@earthlink.net | K2: Physical | L2: Citywide
A3: Barry | B3: Perkins | C3: =A3&" "&B3 -> Barry Perkins | D3: - | E3: 2140 Pine Street | F3: San Francisco | G3: CA | H3: 94115 | I3: 415-990-0234 | J3: barry_perkins@yahoo.com | K3: Physical | L3: Western Addition
A4: Marianne | B4: Hesse | C4: =A4&" "&B4 -> Marianne Hesse | D4: - | E4: 101 Belvedere Street | F4: San Francisco | G4: CA | H4: 94117 | I4: 415-665-3657 | J4: mhesse@pacbell.net | K4: Physical | L4: Haight Ashbury
A5: James | B5: Fisher | C5: =A5&" "&B5 -> James Fisher | D5: - | E5: 10495 N De Anza Blvd MS 74-2RC | F5: Cupertino | G5: CA | H5: 95014 | I5: 262-352-9498 | J5: j.benjamin.fisher@gmail.com | K5: Physical | L5: Western Addition
A6: Georgia | B6: Schuttish | C6: =A6&" "&B6 -> Georgia Schuttish | D6: - | E6: 460 Duncan Street | F6: San Francisco | G6: CA | H6: 94131 | I6: - | J6: schuttishtr@sbcglobal.net | K6: Physical | L6: Noe Valley
A7: Russel | B7: Morine | C7: =A7&" "&B7 -> Russel Morine | D7: - | E7: 64 Gillette Avenue | F7: San Francisco | G7: CA | H7: 94134 | I7: 415-740-4014 | J7: rmorine@aol.com | K7: Physical | L7: Bayview
A8: Edward | B8: Stiel | C8: =A8&" "&B8 -> Edward Stiel | D8: 2887 Folsom Street Concerned Residents | E8: 2887 Folsom Street | F8: San Francisco | G8: CA | H8: 94110 | I8: 415-282-5393 | J8: eddiestiel@yahoo.com | K8: Electronic | L8: Mission
C9: Michelle Brown | D9: 318 Frederick St. Tenancy In Common Owner's Association and Board | E9: 318 Frederick Street | F9: San Francisco | G9: CA | H9: 94117 | I9: 415-608-3945 | J9: brownmi@stanford.edu | K9: Electronic | L9: Haight Ashbury
A10: Jeffrey | B10: Kwong | C10: =A10&" "&B10 -> Jeffrey Kwong | D10: District 3 Tenants | E10: 1754 Hyde Street | F10: San Francisco | G10: CA | H10: 94106 | I10: 415-290-5595 | J10: cardinalsf@gmail.com | K10: Physical | L10: Chinatown, Downtown Civic Center, Financial District, Nob Hill, North Beach
A11: Sara | B11: Bartholomew | C11: Marilyn Hersh | D11: 19th Street/Oakwood Neighborhood Association | E11: 3696 19th Street | F11: San Francisco | G11: CA | H11: 94110 | I11: - | J11: hershmari@gmail.com | K11: Electronic | L11: Mission
C12: Leslie Chin | D12: 19th Street/Oakwood Neighborhood Association | E12: 41 Oakwood | F12: San Francisco | G12: CA | H12: 94110 | I12: - | J12: lchinflute@gmail.com | K12: Electronic | L12: Mission
A13: ASNA | B13: Board | C13: =A13&" "&B13 -> ASNA Board | D13: Alamo Square Neighborhood Assocation | E13: 530 Divisadero Street #176 | F13: San Francisco | G13: CA | H13: 94117 | I13: 415-271-5691 | J13: board@alamosq.org | K13: Electronic | L13: Western Addition
A14: Michael | B14: Nulty | C14: =A14&" "&B14 -> Michael Nulty | D14: Alliance for a Better District 6 | E14: P.O. Box 420782 | F14: San Francisco | G14: CA | H14: 94142 | I14: 415-339-8779 | J14: sf_district6@yahoo.com | K14: Physical | L14: Downtown/Civic Center, Financial District, Mission, Nob Hill, South of Market, Treasure Island, Western Addition
A15: Laura | B15: Magnani | C15: =A15&" "&B15 -> Laura Magnani | D15: American Friends Service Committee | E15: 65 Ninth Street | F15: San Francisco | G15: CA | H15: 94103 | I15: 415-565-0201 | J15: sfoffice@afsc.org | K15: Physical | L15: South of Market
A16: Linda | B16: Burton | C16: =A16&" "&B16 -> Linda Burton | D16: Anna Waden Library | E16: 5075 3rd Street | F16: San Francisco | G16: CA | H16: 94124 | I16: 415-715-4100 | K16: Physical | L16: Bayview
A17: Al | B17: Sodini | C17: =A17&" "&B17 -> Al Sodini | D17: Anza Vista Civic Improvement Club | E17: 140 Terra Vista Avenue | F17: San Francisco | G17: CA | H17: 94115 | I17: 415-921-5131 | J17: ducha931@aol.com | K17: Physical | L17: Western Addition
C18: =A18&" "&B18 | D18: Asian Pacific American Community Center | E18: 50 Raymond Ave | F18: San Francisco | G18: CA | H18: 94134 | I18: 415-587-2689 | J18: info@apaccsf.org | K18: Physical | L18: Visitacion Valley
A19: Construction | B19: and Engineering | C19: =A19&" "&B19 -> Construction and Engineering | D19: AT&T | E19: 359 Washington Street, Room 205 | F19: Daly City | G19: CA | H19: 94015 | K19: Physical | L19: Citywide
C20: SatKartar Khalsa | D20: Avila Street Corridor | E20: 333 Avila Street | F20: San Francisco | G20: CA | H20: 94123 | I20: 415-810-2246 | J20: avilastreetcorridor@gmail.com | K20: Electronic | L20: Marina
A21: Board | B21: of Directors | C21: =A21&" "&B21 -> Board of Directors | D21: Balboa Terrace Homes Association | E21: P.O. Box 27642 | F21: San Francisco | G21: CA | H21: 94127 | I21: 415-279-9530 | J21: bthaboard@balboaterrace.org | K21: Electronic | L21: West of Twin Peaks
A22: Yuka | B22: Ioroi | C22: =A22&" "&B22 -> Yuka Ioroi | D22: Balboa Village Merchants Association | E22: 3519 Balboa Street | F22: San Francisco | G22: CA | H22: 94121 | I22: 626-419-2190 | J22: yukaioroi@gmail.com | K22: Physical | L22: Outer Richmond
A23: Diana | B23: Taylor | C23: =A23&" "&B23 -> Diana Taylor | D23: Barbary Coast Neighborhood Association | E23: P.O. Box 2045 | F23: San Francisco | G23: CA | H23: 94126 | I23: - | J23: bcna@bcnasf.org | K23: Electronic | L23: Financial District, North Beach
A24: Daniel | B24: Dodt | C24: =A24&" "&B24 -> Daniel Dodt | D24: BayView Community Planning | E24: 2027 Oakdale Avenue | F24: San Francisco | G24: CA | H24: 94124 | I24: 415-730-2071 | J24: bvhpwatch@mac.com | K24: Electronic | L24: Bayview
A25: Board | B25: Secretary | C25: =A25&" "&B25 -> Board Secretary | D25: Bayview Hill Neighborhood Association | J25: bvhna.secretary@gmail.com bayviewhillsf@gmail.com | K25: Electronic | L25: Bayview
A26: Philip | B26: Williams | D26: Bayview Hunters Point Citizens Advisory Committee | E26: 1550 Evans Avenue | F26: San Francisco | G26: CA | H26: 94124 | J26: bayviewcac@sfgov.org | K26: Electronic | L26: Bayview
A27: Sophie | B27: Constantinou | C27: =A27&" "&B27 -> Sophie Constantinou | D27: Bernal Cut Neighborhood Alliace | E27: 22 Richland Avenue | F27: San Francisco | G27: CA | H27: 94110 | I27: 415-378-6085 | J27: bernalcutpath@gmail.com | K27: Electronic | L27: Bernal Heights, Glen Park
A28: Wendy | B28: Cowles | C28: =A28&" "&B28 -> Wendy Cowles | D28: Bernal Heights East Slope Design Review Board | E28: 89 Banks Street | F28: San Francisco | G28: CA | H28: 94110 | J28: bhesdrb@gmail.com | K28: Electronic | L28: Bernal Heights
A29: Rachel | B29: Ebora | C29: =A29&" "&B29 -> Rachel Ebora | D29: Bernal Heights Housing Corporation | E29: 515 Cortland Avenue | F29: San Francisco | G29: CA | H29: 94110 | K29: Physical | L29: Bernal Heights
A30: Barbara | B30: Lopez | C30: Sulaiman Hyatt | D30: Bernal Heights Neighborhood Center | E30: 1591 Treat Avenue | F30: San Francisco | G30: CA | H30: 94110 | I30: 415-206-2140 | J30: shyatt@bhnc.org | K30: Electronic | L30: Bernal Heights
A31: Andre | B31: Rothblatt | C31: =A31&" "&B31 -> Andre Rothblatt | D31: Bernal Heights Preservation | E31: 475 Nevada Street | F31: San Francisco | G31: CA | H31: 94110 | I31: 415-626-5112 | J31: arothblatt@aol.com | K31: Physical | L31: Bernal Heights
A32: Kathy | B32: Angus | C32: =A32&" "&B32 -> Kathy Angus | D32: Bernal Heights South Slope Organization | E32: 99 Banks Street | F32: San Francisco | G32: CA | H32: 94110 | I32: 415-282-9223 | J32: kathyangus@gmail.com | K32: Electronic | L32: Bernal Heights
C33: Josephine Zhao | D33: Better Housing Policies | E33: 945 Taraval Street | F33: San Francisco | G33: CA | H33: 94116 | I33: 415-871-5715 | J33: info@betterhousingpolicies.org | K33: Electronic | L33: Excelsior, Outer Richmond, Outer Sunset, Parkside, Visitacion Valley
A34: Shamann | B34: Walton | C34: =A34&" "&B34 -> Shamann Walton | D34: Board of Supervisors | E34: 1 Dr. Carlton B Goodlett Place, Room #244 | F34: San Francisco | G34: CA | H34: 94102-4689 | I34: - | J34: waltonstaff@sfgov.org; Percy.Burch@sfgov.org; Tracy.Gallardo@sfgov.org; Natalie.Gee@sfgov.org | K34: Both | L34: Bayview, Potrero Hill, Visitacion Valley
A35: Dean | B35: Preston | C35: Bilal Mahmood | D35: Board of Supervisors | E35: 1 Dr. Carlton B Goodlett Place, Room #244 | F35: San Francisco | G35: CA | H35: 94102-4689 | I35: - | J35: MahmoodStaff@sfgov.org; Raynell.Cooper@sfgov.org | K35: Both | L35: Downtown/Civic Center, Haight Ashbury, Western Addition
A36: Aaron | B36: Peskin | C36: Danny Sauter | D36: Board of Supervisors | E36: 1 Dr. Carlton B Goodlett Place, Room #244 | F36: San Francisco | G36: CA | H36: 94102-4689 | I36: - | J36: SauterStaff@sfgov.org; Michelle.Andrews@sfgov.org; Amy.Lee5@sfgov.org; tita.bell@sfgov.org; tomio.nagano@sfgov.org | K36: Both | L36: Chinatown, Financial District, Nob Hill, North Beach, Russian Hill
A37: Ahsha | B37: Safai | C37: Chyanne Chen | D37: Board of Supervisors | E37: 1 Dr. Carlton B Goodlett Place, Room #244 | F37: San Francisco | G37: CA | H37: 94102-4689 | I37: - | J37: ChenStaff@sfgov.org; Charlie.Sciammas@sfgov.org | K37: Both | L37: Crocker Amazon, Excelsior, Outer Mission, Visitacion Valley
A38: Rafael | B38: Mandelman | C38: =A38&" "&B38 -> Rafael Mandelman | D38: Board of Supervisors | E38: 1 Dr. Carlton B Goodlett Place, Room #244 | F38: San Francisco | G38: CA | H38: 94102-4689 | I38: - | J38: Rafael.Mandelman@sfgov.org; Kyle.Smeallie@sfgov.org; Tom.Temprano@sfgov.org; jacob.bintliff@sfgov.org; mandelmanstaff@sfgov.org | K38: Both | L38: Castro/Upper Market, Diamond Heights, Glen Park, Noe Valley, Twin Peaks
A39: Connie | B39: Chan | C39: =A39&" "&B39 -> Connie Chan | D39: Board of Supervisors | E39: 1 Dr. Carlton B Goodlett Place, Room #244 | F39: San Francisco | G39: CA | H39: 94102-4689 | I39: - | J39: connie.chan@sfgov.org; ian.fregosi@sfgov.org; frances.hsieh@sfgov.org; kelly.groth@sfgov.org; angelina.yu@sfgov.org; ChanStaff@sfgov.org | K39: Both | L39: Inner Richmond, Outer Richmond, Seacliff
A40: Myrna | B40: Melgar | C40: =A40&" "&B40 -> Myrna Melgar | D40: Board of Supervisors | E40: 1 Dr. Carlton B Goodlett Place, Room #244 | F40: San Francisco | G40: CA | H40: 94102-4689 | I40: - | J40: myrna.melgar@sfgov.org; Jennifer.Fieber@sfgov.org; Megan.Imperial@sfgov.org; Lila.Carrillo@sfgov.org; Jen.Low@sfgov.org; melgarstaff@sfgov.org | K40: Both | L40: Inner Sunset, Lakeshore, Ocean View, Parkside, Twin Peaks, West of Twin Peaks
...

Sheet Citywide
A1: ORGANIZATION | B1: ='Complete List_09252026'!C1 -> NAME | C1: ='Complete List_09252026'!E1 -> ADDRESS | D1: ='Complete List_09252026'!F1 -> CITY | E1: ='Complete List_09252026'!G1 -> STATE | F1: ='Complete List_09252026'!H1 -> ZIP | G1: ='Complete List_09252026'!J1 -> EMAIL | H1: NOTIFICATION PREFERENCES | I1: ='Complete List_09252026'!L1 -> NEIGHBORHOOD OF INTEREST
A2: PHYSICAL NOTICES
A3: AT&T | B3: ='Complete List_09252026'!C19 -> Construction and Engineering | C3: ='Complete List_09252026'!E19 -> 359 Washington Street, Room 205 | D3: ='Complete List_09252026'!F19 -> Daly City | E3: ='Complete List_09252026'!G19 -> CA | F3: ='Complete List_09252026'!H19 -> 94015 | G3: ='Complete List_09252026'!J19 -> 0 | H3: ='Complete List_09252026'!K19 -> Physical | I3: ='Complete List_09252026'!L19 -> Citywide
A4: Community Design Center | B4: ='Complete List_09252026'!C70 -> Chuck Turner | C4: ='Complete List_09252026'!E70 -> 5 Thomas Mellon Circle, #128 | D4: ='Complete List_09252026'!F70 -> San Francisco | E4: ='Complete List_09252026'!G70 -> CA | F4: ='Complete List_09252026'!H70 -> 94134 | G4: ='Complete List_09252026'!J70 -> charles.turner@communitydesigncentersf.com | H4: ='Complete List_09252026'!K70 -> Physical | I4: ='Complete List_09252026'!L70 -> Citywide
A5: SF Building and Construction Trades Council | B5: ='Complete List_09252026'!C250 -> Tim Paulson Rudy Gonzalez | C5: ='Complete List_09252026'!E250 -> 1188 Franklin Street, Ste.203 | D5: ='Complete List_09252026'!F250 -> San Francisco | E5: ='Complete List_09252026'!G250 -> CA | F5: ='Complete List_09252026'!H250 -> 94109 | G5: ='Complete List_09252026'!J250 -> tim@sfbuildingtradescouncil.org rudy@sfbuildingtradescouncil.org | H5: ='Complete List_09252026'!K250 -> Physical | I5: ='Complete List_09252026'!L250 -> Citywide
A6: - | B6: ='Complete List_09252026'!C2 -> Aaron Peskin | C6: ='Complete List_09252026'!E2 -> 470 Columbus Avenue, Ste. 211 | D6: ='Complete List_09252026'!F2 -> San Francisco | E6: ='Complete List_09252026'!G2 -> CA | F6: ='Complete List_09252026'!H2 -> 94133 | G6: ='Complete List_09252026'!J2 -> aaron.peskin@earthlink.net | H6: ='Complete List_09252026'!K2 -> Physical | I6: ='Complete List_09252026'!L2 -> Citywide
A7: Carpenters Local 22 | B7: ='Complete List_09252026'!C51 -> Leonard Basoco | C7: ='Complete List_09252026'!E51 -> 2085 Third Street | D7: ='Complete List_09252026'!F51 -> San Francisco | E7: ='Complete List_09252026'!G51 -> CA | F7: ='Complete List_09252026'!H51 -> 94107 | G7: ='Complete List_09252026'!J51 -> ASimi@nccrc.org | H7: ='Complete List_09252026'!K51 -> Physical | I7: ='Complete List_09252026'!L51 -> Citywide
A8: Coalition for Adequate Review | B8: ='Complete List_09252026'!C65 -> Mary Miles | C8: ='Complete List_09252026'!E65 -> 364 Page Street, #36 | D8: ='Complete List_09252026'!F65 -> San Francisco | E8: ='Complete List_09252026'!G65 -> CA | F8: ='Complete List_09252026'!H65 -> 94102 | G8: ='Complete List_09252026'!J65 -> 0 | H8: ='Complete List_09252026'!K65 -> Physical | I8: ='Complete List_09252026'!L65 -> Citywide
A9: Coalition for San Francisco Neighborhodos (CSFN) | B9: ='Complete List_09252026'!C66 -> George Wooding / Rose Hillson | C9: ='Complete List_09252026'!E66 -> P.O. Box 156616 | D9: ='Complete List_09252026'!F66 -> San Francisco | E9: ='Complete List_09252026'!G66 -> CA | F9: ='Complete List_09252026'!H66 -> 94115-6616 | G9: ='Complete List_09252026'!J66 -> CSFNnotices@gmail.com | H9: ='Complete List_09252026'!K66 -> Physical | I9: ='Complete List_09252026'!L66 -> Citywide
A10: Law Office of Stephen M. Williams | B10: ='Complete List_09252026'!C152 -> Stephen Williams | C10: ='Complete List_09252026'!E152 -> 1934 Divisadero Street | D10: ='Complete List_09252026'!F152 -> San Francisco | E10: ='Complete List_09252026'!G152 -> CA | F10: ='Complete List_09252026'!H152 -> 94115 | G10: ='Complete List_09252026'!J152 -> SMW@stevewilliamslaw.com | H10: ='Complete List_09252026'!K152 -> Physical | I10: ='Complete List_09252026'!L152 -> Citywide
A11: BOTH PHYSICAL & ELECTRONIC NOTICES
A12: Lozeau Drury LLP | B12: Maya Vishwanath | C12: 1939 Harrison Street, Suite 150 | D12: Oakland | E12: CA | F12: 94612 | G12: michael@lozeaudrury.com hannah@lozeaudrury.com maya@lozeaudrury.com | H12: Both | I12: Citywide
A13: ELECTRONIC NOTICES
A14: San Francisco Tenants Union | B14: ='Complete List_09252026'!C243 -> Layla Stanley | C14: ='Complete List_09252026'!E243 -> 558 Capp Street | D14: ='Complete List_09252026'!F243 -> San Francisco | E14: ='Complete List_09252026'!G243 -> CA | F14: ='Complete List_09252026'!H243 -> 94110 | G14: ='Complete List_09252026'!J243 -> sfplanningnotice@SFTU.org | H14: ='Complete List_09252026'!K243 -> Electronic | I14: ='Complete List_09252026'!L243 -> Citywide
A15: San Francisco Electrical Construction Industry (SFECI) | B15: ='Complete List_09252026'!C254 -> Alex Lantsberg | C15: ='Complete List_09252026'!E254 -> 55 Fillmore Street | D15: ='Complete List_09252026'!F254 -> San Francisco | E15: ='Complete List_09252026'!G254 -> CA | F15: ='Complete List_09252026'!H254 -> 94117 | G15: ='Complete List_09252026'!J254 -> alex@sfeci.org | H15: ='Complete List_09252026'!K254 -> Electronic | I15: ='Complete List_09252026'!L254 -> Citywide
A16: Sheet Metal Workers Local Union No. 104 | B16: ='Complete List_09252026'!C260 -> Danny Campbell | C16: ='Complete List_09252026'!E260 -> 1939 Market Street, Suite A | D16: ='Complete List_09252026'!F260 -> San Francisco | E16: ='Complete List_09252026'!G260 -> CA | F16: ='Complete List_09252026'!H260 -> 94103 | G16: ='Complete List_09252026'!J260 -> dannyc@smw104.org | H16: ='Complete List_09252026'!K260 -> Electronic | I16: ='Complete List_09252026'!L260 -> Citywide
A17: SOMA Neighborhood Association | B17: ='Complete List_09252026'!C265 -> John Valdez | C17: ='Complete List_09252026'!E265 -> 2 Townsend Street, 3-105 | D17: ='Complete List_09252026'!F265 -> San Francisco | E17: ='Complete List_09252026'!G265 -> CA | F17: ='Complete List_09252026'!H265 -> 94107 | G17: ='Complete List_09252026'!J265 -> sfloans@sbcglobal.net | H17: ='Complete List_09252026'!K265 -> Electronic | I17: ='Complete List_09252026'!L265 -> Citywide
A18: ='Complete List_09252026'!D256 -> San Francisco SAFE, Inc. | B18: ='Complete List_09252026'!C256 -> Kyra Worthy | C18: ='Complete List_09252026'!E256 -> 850 Bryant Street, Room 135 | D18: ='Complete List_09252026'!F256 -> San Francisco | E18: ='Complete List_09252026'!G256 -> CA | F18: ='Complete List_09252026'!H256 -> 94103 | G18: ='Complete List_09252026'!J256 -> info@sfsafe.org | H18: ='Complete List_09252026'!K256 -> Electronic | I18: ='Complete List_09252026'!L256 -> Citywide
A19: ='Complete List_09252026'!D182 -> Mission Awareness Project | B19: ='Complete List_09252026'!C182 -> Morgan Noble | C19: ='Complete List_09252026'!E182 -> 1198 S. Van Ness Ave #104 | D19: ='Complete List_09252026'!F182 -> San Francisco | E19: ='Complete List_09252026'!G182 -> CA | F19: ='Complete List_09252026'!H182 -> 94110 | G19: ='Complete List_09252026'!J182 -> info@missionawarenessproject.com | H19: ='Complete List_09252026'!K182 -> Electronic | I19: ='Complete List_09252026'!L182 -> Citywide

Sheet Bayview
A1: ORGANIZATION | B1: ='Complete List_09252026'!C1 -> NAME | C1: ='Complete List_09252026'!E1 -> ADDRESS | D1: ='Complete List_09252026'!F1 -> CITY | E1: ='Complete List_09252026'!G1 -> STATE | F1: ='Complete List_09252026'!H1 -> ZIP | G1: ='Complete List_09252026'!J1 -> EMAIL | H1: NOTIFICATION PREFERENCES | I1: ='Complete List_09252026'!L1 -> NEIGHBORHOOD OF INTEREST
A2: PHYSICAL NOTICES
A3: Anna Waden Library | B3: ='Complete List_09252026'!C16 -> Linda Burton | C3: ='Complete List_09252026'!E16 -> 5075 3rd Street | D3: ='Complete List_09252026'!F16 -> San Francisco | E3: ='Complete List_09252026'!G16 -> CA | F3: ='Complete List_09252026'!H16 -> 94124 | G3: ='Complete List_09252026'!J16 -> 0 | H3: ='Complete List_09252026'!K16 -> Physical | I3: ='Complete List_09252026'!L95 -> Bayview, Castro/Upper Market
A4: EqualitySF | C4: ='Complete List_09252026'!E99 -> P.O. Box 24297 | D4: ='Complete List_09252026'!F99 -> San Francisco | E4: ='Complete List_09252026'!G99 -> CA | F4: ='Complete List_09252026'!H99 -> 94124 | G4: ='Complete List_09252026'!J99 -> 0 | H4: ='Complete List_09252026'!K99 -> Physical | I4: ='Complete List_09252026'!L99 -> Bayview
A5: Samoan Development Centre | B5: ='Complete List_09252026'!C242 -> Patsy Tito | C5: ='Complete List_09252026'!E242 -> 2055 Sunnydale Avenue #100 | D5: ='Complete List_09252026'!F242 -> San Francisco | E5: ='Complete List_09252026'!G242 -> CA | F5: ='Complete List_09252026'!H242 -> 94134-2611 | G5: ='Complete List_09252026'!J242 -> 0 | H5: ='Complete List_09252026'!K242 -> Physical | I5: ='Complete List_09252026'!L25 -> Bayview
A6: Sherwin Williams | B6: ='Complete List_09252026'!C261 -> Francesca Panullo | C6: ='Complete List_09252026'!E261 -> 1415 Ocean Ave | D6: ='Complete List_09252026'!F261 -> San Francisco | E6: ='Complete List_09252026'!G261 -> CA | F6: ='Complete List_09252026'!H261 -> 94112 | G6: ='Complete List_09252026'!J261 -> sw8644@sherwin.com | H6: ='Complete List_09252026'!K261 -> Physical | I6: ='Complete List_09252026'!L248 -> Bayview, Potrero Hill, Visitacion Valley
A7: Southeast Community Facility | B7: ='Complete List_09252026'!C272 -> Larry Berry | C7: ='Complete List_09252026'!E272 -> 1800 Oakdale Avenue | D7: ='Complete List_09252026'!F272 -> San Francisco | E7: ='Complete List_09252026'!G272 -> CA | F7: ='Complete List_09252026'!H272 -> 94124 | G7: ='Complete List_09252026'!J272 -> 0 | H7: ='Complete List_09252026'!K272 -> Physical | I7: ='Complete List_09252026'!L258 -> Bayview
A8: St. Paul of the Shipwreck Church | B8: ='Complete List_09252026'!C276 -> Paul Gawlowski | C8: ='Complete List_09252026'!E276 -> 1122 Jamestown Aveue | D8: ='Complete List_09252026'!F276 -> San Francisco | E8: ='Complete List_09252026'!G276 -> CA | F8: ='Complete List_09252026'!H276 -> 94124 | G8: ='Complete List_09252026'!J276 -> spswoffice@aol.com | H8: ='Complete List_09252026'!K276 -> Physical | I8: ='Complete List_09252026'!L133 -> Bayview
A9: - | B9: ='Complete List_09252026'!C7 -> Russel Morine | C9: ='Complete List_09252026'!E7 -> 64 Gillette Avenue | D9: ='Complete List_09252026'!F7 -> San Francisco | E9: ='Complete List_09252026'!G7 -> CA | F9: ='Complete List_09252026'!H7 -> 94134 | G9: ='Complete List_09252026'!J7 -> rmorine@aol.com | H9: ='Complete List_09252026'!K7 -> Physical | I9: ='Complete List_09252026'!L242 -> Bayview, South of Market
A10: Eureka Valley Trails/Art Network | B10: ='Complete List_09252026'!C95 -> Bruce Murphy | C10: ='Complete List_09252026'!E95 -> 1281 Quesada Ave | D10: ='Complete List_09252026'!F95 -> San Francisco | E10: ='Complete List_09252026'!G95 -> CA | F10: ='Complete List_09252026'!H95 -> 94124-3334 | G10: ='Complete List_09252026'!J95 -> luckylaowai.sf@gmail.com | H10: ='Complete List_09252026'!K95 -> Physical | I10: ='Complete List_09252026'!L276 -> Bayview
A11: Portola Place Homeowners Association | B11: ='Complete List_09252026'!C231 -> David Gilliam | C11: ='Complete List_09252026'!E231 -> P.O. Box 24181 | D11: ='Complete List_09252026'!F231 -> San Francisco | E11: ='Complete List_09252026'!G231 -> CA | F11: ='Complete List_09252026'!H231 -> 94124-0181 | G11: ='Complete List_09252026'!J231 -> dgumpire@aol.com | H11: ='Complete List_09252026'!K231 -> Physical | I11: ='Complete List_09252026'!L272 -> Bayview
A12: Shafter Avenue Community Club | B12: ='Complete List_09252026'!C258 -> Maverick Madison | C12: ='Complete List_09252026'!E258 -> 1629 Shafter Avenue | D12: ='Complete List_09252026'!F258 -> San Francisco | E12: ='Complete List_09252026'!G258 -> CA | F12: ='Complete List_09252026'!H258 -> 94124 | G12: ='Complete List_09252026'!J258 -> misterfingers04@yahoo.com | H12: ='Complete List_09252026'!K258 -> Physical | I12: ='Complete List_09252026'!L99 -> Bayview
A13: BOTH PHYSICAL & ELECTRONIC NOTICES
A14: Board of Supervisors | B14: ='Complete List_09252026'!C34 -> Shamann Walton | C14: ='Complete List_09252026'!E34 -> 1 Dr. Carlton B Goodlett Place, Room #244 | D14: ='Complete List_09252026'!F34 -> San Francisco | E14: ='Complete List_09252026'!G34 -> CA | F14: ='Complete List_09252026'!H34 -> 94102-4689 | G14: ='Complete List_09252026'!J34 -> waltonstaff@sfgov.org; Percy.Burch@sfgov.org; Tracy.Gallardo@sfgov.org; Natalie.Gee@sfgov.org | H14: ='Complete List_09252026'!K34 -> Both | I14: ='Complete List_09252026'!L34 -> Bayview, Potrero Hill, Visitacion Valley
A15: India Basin Neighborhood Association | B15: ='Complete List_09252026'!C133 -> Michael Hamman | C15: ='Complete List_09252026'!E133 -> 702 Earl Street | D15: ='Complete List_09252026'!F133 -> San Francisco | E15: ='Complete List_09252026'!G133 -> CA | F15: ='Complete List_09252026'!H133 -> 94124 | G15: ='Complete List_09252026'!J133 -> mhamman@igc.org; info@indiabasin.org | H15: ='Complete List_09252026'!K133 -> Both | I15: ='Complete List_09252026'!L133 -> Bayview
A16: ELECTRONIC NOTICES
A17: BayView Community Planning | B17: ='Complete List_09252026'!C24 -> Daniel Dodt | C17: ='Complete List_09252026'!E24 -> 2027 Oakdale Avenue | D17: ='Complete List_09252026'!F24 -> San Francisco | E17: ='Complete List_09252026'!G24 -> CA | F17: ='Complete List_09252026'!H24 -> 94124 | G17: ='Complete List_09252026'!J24 -> bvhpwatch@mac.com | H17: ='Complete List_09252026'!K24 -> Electronic | I17: ='Complete List_09252026'!L261 -> Bayview, Bernal Heights, Crocker Amazon, Diamond Heights, Excelsior, Glen Park, Inner Sunset, Lakeshore, Noe Valley, Ocean View, Outer Mission, Outer Sunset, Parkside, Potrero Hill, South Bayshore, Twin Peaks, Visitacion Valley, West of Twin Peaks
A18: Bayview Hunters Point Citizens Advisory Committee | C18: ='Complete List_09252026'!E26 -> 1550 Evans Avenue | D18: ='Complete List_09252026'!F26 -> San Francisco | E18: ='Complete List_09252026'!G26 -> CA | F18: ='Complete List_09252026'!H26 -> 94124 | G18: ='Complete List_09252026'!J26 -> bayviewcac@sfgov.org | H18: ='Complete List_09252026'!K26 -> Electronic | I18: ='Complete List_09252026'!L26 -> Bayview
A19: Economic Development on Third (EDoT) | B19: ='Complete List_09252026'!C89 -> Earl Shaddix | C19: ='Complete List_09252026'!E89 -> 4800 Third Street #404 | D19: ='Complete List_09252026'!F89 -> San Francisco | E19: ='Complete List_09252026'!G89 -> CA | F19: ='Complete List_09252026'!H89 -> 94124 | G19: ='Complete List_09252026'!J89 -> earl@edotbayview.com | H19: ='Complete List_09252026'!K89 -> Electronic | I19: ='Complete List_09252026'!L89 -> Bayview
A20: Greenaction for Health and Environmental Justice | B20: ='Complete List_09252026'!C119 -> Bradley Angel | C20: ='Complete List_09252026'!E119 -> 315 Sutter Street, 2nd Floor | D20: ='Complete List_09252026'!F119 -> San Francisco | E20: ='Complete List_09252026'!G119 -> CA | F20: ='Complete List_09252026'!H119 -> 94108 | G20: ='Complete List_09252026'!J119 -> greenaction@greenaction.org | H20: ='Complete List_09252026'!K119 -> Electronic | I20: ='Complete List_09252026'!#REF! -> #REF!
A21: SF Bay View Newspaper | B21: ='Complete List_09252026'!C248 -> Nube Brown | C21: ='Complete List_09252026'!E248 -> 4917 Third Street | D21: ='Complete List_09252026'!F248 -> San Francisco | E21: ='Complete List_09252026'!G248 -> CA | F21: ='Complete List_09252026'!H248 -> 94124 | G21: ='Complete List_09252026'!J248 -> editor@sfbayview.com | H21: ='Complete List_09252026'!K248 -> Electronic | I21: ='Complete List_09252026'!L26 -> Bayview
A22: Young Community Developers (YCD) | B22: ='Complete List_09252026'!C317 -> Zachary Weisenburger | C22: ='Complete List_09252026'!E317 -> 1715 Yosemite Avenue | D22: ='Complete List_09252026'!F317 -> San Francisco | E22: ='Complete List_09252026'!G317 -> CA | F22: ='Complete List_09252026'!H317 -> 94124 | G22: ='Complete List_09252026'!J317 -> zweisenburger@ycdjobs.org | H22: ='Complete List_09252026'!K317 -> Electronic | I22: ='Complete List_09252026'!L217 -> Bayview, Crocker Amazon, Excelsior, Ocean View, Potrero Hill, Visitacion Valley
A23: Bayview Hill Neighborhood Association | B23: ='Complete List_09252026'!C25 -> Board Secretary | C23: ='Complete List_09252026'!E25 -> 0 | D23: ='Complete List_09252026'!F25 -> 0 | E23: ='Complete List_09252026'!G25 -> 0 | F23: ='Complete List_09252026'!H25 -> 0 | G23: ='Complete List_09252026'!J25 -> bvhna.secretary@gmail.com bayviewhillsf@gmail.com | H23: ='Complete List_09252026'!K25 -> Electronic | I23: ='Complete List_09252026'!L7 -> Bayview
A24: ='Complete List_09252026'!D45 -> Both Sides of the Conversation | B24: ='Complete List_09252026'!C45 -> Jon Henry | C24: ='Complete List_09252026'!E45 -> P.O. Box 347518 | D24: ='Complete List_09252026'!F45 -> San Francisco | E24: ='Complete List_09252026'!G45 -> CA | F24: ='Complete List_09252026'!H45 -> 94134 | G24: ='Complete List_09252026'!J45 -> jonhenry@bsotc.org | H24: ='Complete List_09252026'!K45 -> Electronic | I24: ='Complete List_09252026'!L45 -> Bayview, Bernal Heights, Crocker Amazon, Downtown/Civic Center, Excelsior, Glen Park, Haight Ashbury, Potrero Hill, South of Market, Treasure Island, Visitacion Valley, West of Twin Peaks, Western Addition
A25: ='Complete List_09252026'!D154 -> Liberation Alliance for Economic and Social Change | B25: ='Complete List_09252026'!C154 -> Keith Pavlik | C25: ='Complete List_09252026'!E154 -> 2969 Mission Street | D25: ='Complete List_09252026'!F154 -> San Francisco | E25: ='Complete List_09252026'!G154 -> CA | F25: ='Complete List_09252026'!H154 -> 94110 | G25: ='Complete List_09252026'!J154 -> info@liberationalliance.org | H25: ='Complete List_09252026'!K154 -> Electronic | I25: ='Complete List_09252026'!L154 -> Bayview, Bernal Heights, Castro/Upper Market, Chinatown, Downtown/Civic Center, Excelsior, Mission, Nob Hill, Noe Valley, Outer Mission, Potrero Hill, South of Market, Western Addition
A26: ='Complete List_09252026'!D249 -> SF Black Wallstreet | B26: ='Complete List_09252026'!C249 -> Tiffany Carter | C26: ='Complete List_09252026'!E249 -> 744 Innes Avenue | D26: ='Complete List_09252026'!F249 -> San Francisco | E26: ='Complete List_09252026'!G249 -> CA | F26: ='Complete List_09252026'!H249 -> 94124 | G26: ='Complete List_09252026'!J249 -> tiffanysfblackwallstreet@gmail.com | H26: ='Complete List_09252026'!K249 -> Electronic | I26: ='Complete List_09252026'!L249 -> Bayview
A27: ='Complete List_09252026'!D235 -> Rafiki Coalition for Health and Wellness | B27: ='Complete List_09252026'!C235 -> Dr. Monique LeSarre | C27: ='Complete List_09252026'!E235 -> 601 Cesar Chavez Street | D27: ='Complete List_09252026'!F235 -> San Francisco | E27: ='Complete List_09252026'!G235 -> CA | F27: ='Complete List_09252026'!H235 -> 94124 | G27: ='Complete List_09252026'!J235 -> devopmentdirector@rafikicoalition.org | H27: ='Complete List_09252026'!K235 -> Electronic | I27: ='Complete List_09252026'!L235 -> Bayview
A28: ='Complete List_09252026'!D277 -> Stand in Peace International | B28: ='Complete List_09252026'!C277 -> Shervon Hunter | C28: ='Complete List_09252026'!E277 -> 45 Tioga Avenue | D28: ='Complete List_09252026'!F277 -> San Francisco | E28: ='Complete List_09252026'!G277 -> CA | F28: ='Complete List_09252026'!H277 -> 94134 | G28: ='Complete List_09252026'!J277 -> standinpeacecommunityprograms@gmail.com | H28: ='Complete List_09252026'!K277 -> Electronic | I28: ='Complete List_09252026'!L277 -> Bayview, Potrero Hill, Visitacion Valley
A29: ='Complete List_09252026'!D100 -> Family Equity Partners | B29: ='Complete List_09252026'!C100 -> Latoya Pitcher | C29: ='Complete List_09252026'!E100 -> 2111 Lane Street #24196 | D29: ='Complete List_09252026'!F100 -> San Francisco | E29: ='Complete List_09252026'!G100 -> CA | F29: ='Complete List_09252026'!H100 -> 94124 | G29: ='Complete List_09252026'!J100 -> lpitcher@familyequitypartnerssf.org | H29: ='Complete List_09252026'!K100 -> Electronic | I29: ='Complete List_09252026'!L100 -> Bayview
A30: OneBayview | B30: ='Complete List_09252026'!C217 -> Anietie Ekanem | C30: ='Complete List_09252026'!E217 -> 5800 3rd Street #1320 | D30: ='Complete List_09252026'!F217 -> San Francisco | E30: ='Complete List_09252026'!G217 -> CA | F30: ='Complete List_09252026'!H217 -> 94124 | G30: ='Complete List_09252026'!J217 -> sfplanningdepartment@onebayview.com aekanem@onebayview.com | H30: ='Complete List_09252026'!K217 -> Electronic | I30: ='Complete List_09252026'!L217 -> Bayview, Crocker Amazon, Excelsior, Ocean View, Potrero Hill, Visitacion Valley
A31: ='Complete List_09252026'!D84 -> Dogpatch Neighborhood Association | B31: ='Complete List_09252026'!C84 -> Michael Berkowitz | C31: ='Complete List_09252026'!E84 -> 1278 Minnesota Street | D31: ='Complete List_09252026'!F84 -> San Francisco | E31: ='Complete List_09252026'!G84 -> CA | F31: ='Complete List_09252026'!H84 -> 94107 | G31: ='Complete List_09252026'!J84 -> info@dogpatchna.org; president@dogpatchna.org | H31: ='Complete List_09252026'!K84 -> Electronic | I31: ='Complete List_09252026'!L84 -> Bayview, Mission, Potrero Hill, South of Market
A32: ='Complete List_09252026'!D85 -> Dogpatch Neighborhood Association | B32: ='Complete List_09252026'!C85 -> Donovan Lacy | C32: ='Complete List_09252026'!E85 -> 1278 Minnesota Street | D32: ='Complete List_09252026'!F85 -> San Francisco | E32: ='Complete List_09252026'!G85 -> CA | F32: ='Complete List_09252026'!H85 -> 94107 | G32: ='Complete List_09252026'!J85 -> vp@dogpatchna.org | H32: ='Complete List_09252026'!K85 -> Electronic | I32: ='Complete List_09252026'!L85 -> Bayview, Mission, Potrero Hill, South of Market
A33: ='Complete List_09252026'!D146 -> Keep Crocker Real | B33: ='Complete List_09252026'!C146 -> KC Real | C33: ='Complete List_09252026'!E146 -> 0 | D33: ='Complete List_09252026'!F146 -> San Francisco | E33: ='Complete List_09252026'!G146 -> CA | F33: ='Complete List_09252026'!H146 -> 94112 | G33: ='Complete List_09252026'!J146 -> hello@keepcrockerreal.com | H33: ='Complete List_09252026'!K146 -> Electronic | I33: ='Complete List_09252026'!L146 -> Bayview, Crocker Amazon, Excelsior, Glen Park, Outer Mission, Visitacion Valley

Sheet Bernal Heights
A1: ORGANIZATION | B1: ='Complete List_09252026'!C1 -> NAME | C1: ='Complete List_09252026'!E1 -> ADDRESS | D1: ='Complete List_09252026'!F1 -> CITY | E1: ='Complete List_09252026'!G1 -> STATE | F1: ='Complete List_09252026'!H1 -> ZIP | G1: ='Complete List_09252026'!J1 -> EMAIL | H1: NOTIFICATION PREFERENCES | I1: ='Complete List_09252026'!L1 -> NEIGHBORHOOD OF INTEREST
A2: PHYSICAL NOTICES
A3: Bernal Heights Housing Corporation | B3: ='Complete List_09252026'!C29 -> Rachel Ebora | C3: ='Complete List_09252026'!E29 -> 515 Cortland Avenue | D3: ='Complete List_09252026'!F29 -> San Francisco | E3: ='Complete List_09252026'!G29 -> CA | F3: ='Complete List_09252026'!H29 -> 94110 | G3: ='Complete List_09252026'!J29 -> 0 | H3: ='Complete List_09252026'!K29 -> Physical | I3: ='Complete List_09252026'!L29 -> Bernal Heights
A4: Coleridge St. Neighbors | B4: ='Complete List_09252026'!C69 -> Buddy Choy | C4: ='Complete List_09252026'!E69 -> 157 Coleridge Street | D4: ='Complete List_09252026'!F69 -> San Francisco | E4: ='Complete List_09252026'!G69 -> CA | F4: ='Complete List_09252026'!H69 -> 94110 | G4: ='Complete List_09252026'!J69 -> choytate@gmail.com | H4: ='Complete List_09252026'!K69 -> Physical | I4: ='Complete List_09252026'!L69 -> Bernal Heights, Mission, Noe Valley
A5: Florida Slope Association | B5: ='Complete List_09252026'!C103 -> Saskia Verbeck | C5: ='Complete List_09252026'!E103 -> 631 Florida Street | D5: ='Complete List_09252026'!F103 -> San Francisco | E5: ='Complete List_09252026'!G103 -> CA | F5: ='Complete List_09252026'!H103 -> 94110 | G5: ='Complete List_09252026'!J103 -> nohoo999@yahoo.com | H5: ='Complete List_09252026'!K103 -> Physical | I5: ='Complete List_09252026'!L103 -> Bernal Heights
A6: Hop Past Brew Pub | B6: ='Complete List_09252026'!C130 -> Aron Deorsey | C6: ='Complete List_09252026'!E130 -> 2887 Bryant St. | D6: ='Complete List_09252026'!F130 -> San Francisco | E6: ='Complete List_09252026'!G130 -> CA | F6: ='Complete List_09252026'!H130 -> 94110 | G6: ='Complete List_09252026'!J130 -> aron.deorsey@gmail.com | H6: ='Complete List_09252026'!K130 -> Physical | I6: ='Complete List_09252026'!L130 -> Bernal Heights, Outer Mission
A7: Sherwin Williams | B7: ='Complete List_09252026'!C261 -> Francesca Panullo | C7: ='Complete List_09252026'!E261 -> 1415 Ocean Ave | D7: ='Complete List_09252026'!F261 -> San Francisco | E7: ='Complete List_09252026'!G261 -> CA | F7: ='Complete List_09252026'!H261 -> 94112 | G7: ='Complete List_09252026'!J261 -> sw8644@sherwin.com | H7: ='Complete List_09252026'!K261 -> Physical | I7: ='Complete List_09252026'!L261 -> Bayview, Bernal Heights, Crocker Amazon, Diamond Heights, Excelsior, Glen Park, Inner Sunset, Lakeshore, Noe Valley, Ocean View, Outer Mission, Outer Sunset, Parkside, Potrero Hill, South Bayshore, Twin Peaks, Visitacion Valley, West of Twin Peaks
A8: Bernal Heights Preservation | B8: ='Complete List_09252026'!C31 -> Andre Rothblatt | C8: ='Complete List_09252026'!E31 -> 475 Nevada Street | D8: ='Complete List_09252026'!F31 -> San Francisco | E8: ='Complete List_09252026'!G31 -> CA | F8: ='Complete List_09252026'!H31 -> 94110 | G8: ='Complete List_09252026'!J31 -> arothblatt@aol.com | H8: ='Complete List_09252026'!K31 -> Physical | I8: ='Complete List_09252026'!L31 -> Bernal Heights
A9: San Franciscans for Reasonable Growth (SFRG) | B9: ='Complete List_09252026'!C244 -> Sue Hestor | C9: ='Complete List_09252026'!E244 -> 329 Highland Ave | D9: ='Complete List_09252026'!F244 -> San Francisco | E9: ='Complete List_09252026'!G244 -> CA | F9: ='Complete List_09252026'!H244 -> 94110 | G9: ='Complete List_09252026'!J244 -> hestor@earthlink.net | H9: Physical | I9: ='Complete List_09252026'!L244 -> Bernal Heights, Chinatown, Downtown/Civic Center, Mission
A10: BOTH PHYSICAL & ELECTRONIC NOTICES
A11: ='Complete List_09252026'!D44 -> Board of Supervisors | B11: ='Complete List_09252026'!C44 -> Jackie Fielder | C11: ='Complete List_09252026'!E44 -> 1 Dr. Carlton B Goodlett Place, Room #244 | D11: ='Complete List_09252026'!F44 -> San Francisco | E11: ='Complete List_09252026'!G44 -> CA | F11: ='Complete List_09252026'!H44 -> 94102-4689 | G11: ='Complete List_09252026'!J44 -> FielderStaff@sfgov.org; Ana.Herrera@sfgov.org; Preston.Kilgore@sfgov.org | H11: ='Complete List_09252026'!K44 -> Both | I11: ='Complete List_09252026'!L44 -> Bernal Heights, Excelsior, Mission, Visitacion Valley
A12: ELECTRONIC NOTICES
A13: Bernal Cut Neighborhood Alliace | B13: ='Complete List_09252026'!C27 -> Sophie Constantinou | C13: ='Complete List_09252026'!E27 -> 22 Richland Avenue | D13: ='Complete List_09252026'!F27 -> San Francisco | E13: ='Complete List_09252026'!G27 -> CA | F13: ='Complete List_09252026'!H27 -> 94110 | G13: ='Complete List_09252026'!J27 -> bernalcutpath@gmail.com | H13: ='Complete List_09252026'!K27 -> Electronic | I13: ='Complete List_09252026'!L27 -> Bernal Heights, Glen Park
A14: Bernal Heights East Slope Design Review Board | B14: ='Complete List_09252026'!C28 -> Wendy Cowles | C14: ='Complete List_09252026'!E28 -> 89 Banks Street | D14: ='Complete List_09252026'!F28 -> San Francisco | E14: ='Complete List_09252026'!G28 -> CA | F14: ='Complete List_09252026'!H28 -> 94110 | G14: ='Complete List_09252026'!J28 -> bhesdrb@gmail.com | H14: ='Complete List_09252026'!K28 -> Electronic | I14: ='Complete List_09252026'!L28 -> Bernal Heights
A15: Bernal Heights Neighborhood Center | B15: ='Complete List_09252026'!C30 -> Sulaiman Hyatt | C15: ='Complete List_09252026'!E30 -> 1591 Treat Avenue | D15: ='Complete List_09252026'!F30 -> San Francisco | E15: ='Complete List_09252026'!G30 -> CA | F15: ='Complete List_09252026'!H30 -> 94110 | G15: ='Complete List_09252026'!J30 -> shyatt@bhnc.org | H15: ='Complete List_09252026'!K30 -> Electronic | I15: ='Complete List_09252026'!L30 -> Bernal Heights
A16: Bernal Heights South Slope Organization | B16: ='Complete List_09252026'!C32 -> Kathy Angus | C16: ='Complete List_09252026'!E32 -> 99 Banks Street | D16: ='Complete List_09252026'!F32 -> San Francisco | E16: ='Complete List_09252026'!G32 -> CA | F16: ='Complete List_09252026'!H32 -> 94110 | G16: ='Complete List_09252026'!J32 -> kathyangus@gmail.com | H16: ='Complete List_09252026'!K32 -> Electronic | I16: ='Complete List_09252026'!L32 -> Bernal Heights
A17: Mission Local | B17: ='Complete List_09252026'!C186 -> Annika Hom | C17: ='Complete List_09252026'!E186 -> 2489 Mission Street #14 | D17: ='Complete List_09252026'!F186 -> San Francisco | E17: ='Complete List_09252026'!G186 -> CA | F17: ='Complete List_09252026'!H186 -> 94110 | G17: ='Complete List_09252026'!J186 -> joe.rivanobarros@missionlocal.com | H17: ='Complete List_09252026'!K186 -> Electronic | I17: ='Complete List_09252026'!L186 -> Bernal Heights, Mission
A18: Northwest Bernal Heights Design Review Board | B18: ='Complete List_09252026'!C211 | C18: ='Complete List_09252026'!E211 -> 32 Aztec Street | D18: ='Complete List_09252026'!F211 -> San Francisco | E18: ='Complete List_09252026'!G211 -> CA | F18: ='Complete List_09252026'!H211 -> 94110 | G18: ='Complete List_09252026'!J211 -> nwbhdrb@gmail.com | H18: ='Complete List_09252026'!K211 -> Electronic | I18: ='Complete List_09252026'!L211 -> Bernal Heights
A19: Both Sides of the Conversation | B19: Jon Henry | C19: P.O. Box 347518 | D19: San Francisco | E19: CA | F19: 94134 | G19: jonhenry@bsotc.org | H19: Electronic | I19: Bayview, Bernal Heights, Crocker Amazon, Downtown/Civic Center, Excelsior, Glen Park, Haight Ashbury, Potrero Hill, South of Market, Treasure Island, Visitacion Valley, West of Twin Peaks, Western Addition
A20: ='Complete List_09252026'!D53 -> Castro LGBTQ Cultural District | B20: ='Complete List_09252026'!C53 -> Jesse Sanford & Stephen Torres | C20: ='Complete List_09252026'!E53 -> 1800 Market Street | D20: ='Complete List_09252026'!F53 -> San Francisco | E20: ='Complete List_09252026'!G53 -> CA | F20: ='Complete List_09252026'!H53 -> 94102 | G20: ='Complete List_09252026'!J53 -> landuse@castrolgbtq.org | H20: ='Complete List_09252026'!K53 -> Electronic | I20: ='Complete List_09252026'!L53 -> Bernal Heights, Castro/Upper Market, Downtown/Civic Center, Mission, Noe Valley, South of Market
A21: ='Complete List_09252026'!D257 -> SFCOV | B21: ='Complete List_09252026'!C257 -> Chris Lee | C21: ='Complete List_09252026'!E257 -> P.O. Box 883392 | D21: ='Complete List_09252026'!F257 -> San Francisco | E21: ='Complete List_09252026'!G257 -> CA | F21: ='Complete List_09252026'!H257 -> 94188 | G21: ='Complete List_09252026'!J257 -> neighbor@sfcov.org | H21: ='Complete List_09252026'!K257 -> Electronic | I21: ='Complete List_09252026'!L257 -> Bernal Heights, Mission, Potrero Hill
A22: ='Complete List_09252026'!D154 -> Liberation Alliance for Economic and Social Change | B22: ='Complete List_09252026'!C154 -> Keith Pavlik | C22: ='Complete List_09252026'!E154 -> 2969 Mission Street | D22: ='Complete List_09252026'!F154 -> San Francisco | E22: ='Complete List_09252026'!G154 -> CA | F22: ='Complete List_09252026'!H154 -> 94110 | G22: ='Complete List_09252026'!J154 -> info@liberationalliance.org | H22: ='Complete List_09252026'!K154 -> Electronic | I22: ='Complete List_09252026'!L154 -> Bayview, Bernal Heights, Castro/Upper Market, Chinatown, Downtown/Civic Center, Excelsior, Mission, Nob Hill, Noe Valley, Outer Mission, Potrero Hill, South of Market, Western Addition

Sheet Castro Upper Market
A1: ORGANIZATION | B1: ='Complete List_09252026'!C1 -> NAME | C1: ='Complete List_09252026'!E1 -> ADDRESS | D1: ='Complete List_09252026'!F1 -> CITY | E1: ='Complete List_09252026'!G1 -> STATE | F1: ='Complete List_09252026'!H1 -> ZIP | G1: ='Complete List_09252026'!J1 -> EMAIL | H1: NOTIFICATION PREFERENCES | I1: ='Complete List_09252026'!L1 -> NEIGHBORHOOD OF INTEREST
A2: PHYSICAL NOTICES
A3: Castro Area Planning + Action | B3: ='Complete List_09252026'!C52 -> Joe Curtin | C3: ='Complete List_09252026'!E52 -> 584 Castro Street, Suite 169 | D3: ='Complete List_09252026'!F52 -> San Francisco | E3: ='Complete List_09252026'!G52 -> CA | F3: ='Complete List_09252026'!H52 -> 94114 | G3: ='Complete List_09252026'!J52 -> 0 | H3: ='Complete List_09252026'!K52 -> Physical | I3: ='Complete List_09252026'!L52 -> Castro/Upper Market
A4: Eureka Heights Neighborhood Association | B4: ='Complete List_09252026'!C93 -> Priscilla Botsford | C4: ='Complete List_09252026'!E93 -> 382 Eureka Street | D4: ='Complete List_09252026'!F93 -> San Francisco | E4: ='Complete List_09252026'!G93 -> CA | F4: ='Complete List_09252026'!H93 -> 94114 | G4: ='Complete List_09252026'!J93 -> prbotsford@yahoo.com | H4: ='Complete List_09252026'!K93 -> Physical | I4: ='Complete List_09252026'!L93 -> Castro/Upper Market
A5: Hotel Zeppelin | B5: ='Complete List_09252026'!C131 -> Antonio Flores | C5: ='Complete List_09252026'!E131 -> 545 Post Street | D5: ='Complete List_09252026'!F131 -> San Francisco | E5: ='Complete List_09252026'!G131 -> CA | F5: ='Complete List_09252026'!H131 -> 94102 | G5: ='Complete List_09252026'!J131 -> antonio.flores@viceroyhotelgroup.com | H5: ='Complete List_09252026'!K131 -> Physical | I5: ='Complete List_09252026'!L131 -> Castro/Upper Market, Chinatown, Downtown/Civic Center, Financial District, Nob Hill, North Beach, South of Market, Treasure Island
A6: Market/Octavia Community Advisory Comm. | B6: ='Complete List_09252026'!C170 -> Ted Olsson | C6: ='Complete List_09252026'!E170 -> 30 Sharon Street | D6: ='Complete List_09252026'!F170 -> San Francisco | E6: ='Complete List_09252026'!G170 -> CA | F6: ='Complete List_09252026'!H170 -> 94114-1709 | G6: ='Complete List_09252026'!J170 -> olssonted@yahoo.com | H6: ='Complete List_09252026'!K170 -> Physical | I6: ='Complete List_09252026'!L170 -> Castro/Upper Market, Downtown/Civic Center, Mission
A7: Valencia Corridor Merchant Association | B7: ='Complete List_09252026'!C304 -> Sean Quigley | C7: ='Complete List_09252026'!E304 -> 766 Valencia Street, 3rd Floor | D7: ='Complete List_09252026'!F304 -> San Francisco | E7: ='Complete List_09252026'!G304 -> CA | F7: ='Complete List_09252026'!H304 -> 94110 | G7: ='Complete List_09252026'!J304 -> seanq@paxtongate.com | H7: ='Complete List_09252026'!K304 -> Physical | I7: ='Complete List_09252026'!L304 -> Castro/Upper Market, Mission, Potrero Hill
A8: Eureka Valley Trails/Art Network | B8: ='Complete List_09252026'!C95 -> Bruce Murphy | C8: ='Complete List_09252026'!E95 -> 1281 Quesada Ave | D8: ='Complete List_09252026'!F95 -> San Francisco | E8: ='Complete List_09252026'!G95 -> CA | F8: ='Complete List_09252026'!H95 -> 94124-3334 | G8: ='Complete List_09252026'!J95 -> luckylaowai.sf@gmail.com | H8: ='Complete List_09252026'!K95 -> Physical | I8: ='Complete List_09252026'!L95 -> Bayview, Castro/Upper Market
A9: Eureka/17th Street Neighbors | B9: ='Complete List_09252026'!C96 -> Jack Keating | C9: ='Complete List_09252026'!E96 -> 4134 17th Street | D9: ='Complete List_09252026'!F96 -> San Francisco | E9: ='Complete List_09252026'!G96 -> CA | F9: ='Complete List_09252026'!H96 -> 94114 | G9: ='Complete List_09252026'!J96 -> jteamj@comcast.net | H9: ='Complete List_09252026'!K96 -> Physical | I9: ='Complete List_09252026'!L96 -> Castro/Upper Market
A10: BOTH PHYSICAL & ELECTRONIC NOTICES
A11: Board of Supervisors | B11: ='Complete List_09252026'!C38 -> Rafael Mandelman | C11: ='Complete List_09252026'!E38 -> 1 Dr. Carlton B Goodlett Place, Room #244 | D11: ='Complete List_09252026'!F38 -> San Francisco | E11: ='Complete List_09252026'!G38 -> CA | F11: ='Complete List_09252026'!H38 -> 94102-4689 | G11: ='Complete List_09252026'!J38 -> Rafael.Mandelman@sfgov.org; Kyle.Smeallie@sfgov.org; Tom.Temprano@sfgov.org; jacob.bintliff@sfgov.org; mandelmanstaff@sfgov.org | H11: ='Complete List_09252026'!K38 -> Both | I11: ='Complete List_09252026'!L38 -> Castro/Upper Market, Diamond Heights, Glen Park, Noe Valley, Twin Peaks
A12: ='Complete List_09252026'!D263 -> SIPS Review Group | B12: ='Complete List_09252026'!C263 -> Patrick Mooney | C12: ='Complete List_09252026'!E263 -> 62 Carmelita Street | D12: ='Complete List_09252026'!F263 -> San Francisco | E12: ='Complete List_09252026'!G263 -> CA | F12: ='Complete List_09252026'!H263 -> 94117 | G12: ='Complete List_09252026'!J263 -> pmmsfo@gmail.com | H12: ='Complete List_09252026'!K263 -> Both | I12: ='Complete List_09252026'!L263 -> Castro / Upper Market, Haight Ashbury, Western Addition
A13: ELECTRONIC NOTICES
A14: Castro Merchants | B14: ='Complete List_09252026'!C54 -> Nikolas Blanchet | C14: ='Complete List_09252026'!E54 -> 584 Castro Street #333 | D14: ='Complete List_09252026'!F54 -> San Francisco | E14: ='Complete List_09252026'!G54 -> CA | F14: ='Complete List_09252026'!H54 -> 94114 | G14: ='Complete List_09252026'!J54 -> info@castromerchants.com | H14: ='Complete List_09252026'!K54 -> Electronic | I14: ='Complete List_09252026'!L174 -> Castro/Upper Market
A15: Castro Upper Market Community Benefit District | B15: ='Complete List_09252026'!C55 -> Andrea Aiello | C15: ='Complete List_09252026'!E55 -> 693 14th Street | D15: ='Complete List_09252026'!F55 -> San Francisco | E15: ='Complete List_09252026'!G55 -> CA | F15: ='Complete List_09252026'!H55 -> 94114 | G15: ='Complete List_09252026'!J55 -> ExecDirector@CastroCBD.org | H15: ='Complete List_09252026'!K55 -> Electronic | I15: ='Complete List_09252026'!L55 -> Castro/Upper Market, Haight Ashbury, Noe Valley
A16: Dolores Heights Improvement Club-DRC | B16: ='Complete List_09252026'!C86 -> Planning and Land Use Committee | C16: ='Complete List_09252026'!E86 -> 4016 20th Street | D16: ='Complete List_09252026'!F86 -> San Francisco | E16: ='Complete List_09252026'!G86 -> CA | F16: ='Complete List_09252026'!H86 -> 94114 | G16: ='Complete List_09252026'!J86 -> plu@doloresheights.org | H16: ='Complete List_09252026'!K86 -> Electronic | I16: ='Complete List_09252026'!L86 -> Castro/Upper Market, Mission, Noe Valley
A17: Duboce Triangle Neighborhood Association | B17: ='Complete List_09252026'!C87 -> Kevin Riley | C17: ='Complete List_09252026'!E87 -> 2261 Market Street PMB #301 | D17: ='Complete List_09252026'!F87 -> San Francisco | E17: ='Complete List_09252026'!G87 -> CA | F17: ='Complete List_09252026'!H87 -> 94114 | G17: ='Complete List_09252026'!J87 -> landuse@dtna.org | H17: ='Complete List_09252026'!K87 -> Electronic | I17: ='Complete List_09252026'!L87 -> Castro/Upper Market, Western Addition
A18: Eureka Valley Neighborhood Association | B18: ='Complete List_09252026'!C94 -> Jennifer Waggoner | C18: ='Complete List_09252026'!E94 -> P.O. Box 14137 | D18: ='Complete List_09252026'!F94 -> San Francisco | E18: ='Complete List_09252026'!G94 -> CA | F18: ='Complete List_09252026'!H94 -> 94114-2827 | G18: ='Complete List_09252026'!J94 -> president@evna.org | H18: ='Complete List_09252026'!K94 -> Electronic | I18: ='Complete List_09252026'!L94 -> Castro/Upper Market
A19: Hayes Valley Neighborhood Association | B19: ='Complete List_09252026'!C126 -> Jennifer Laska | C19: ='Complete List_09252026'!E126 -> 400 Grove Street, Suite 3 | D19: ='Complete List_09252026'!F126 -> San Francisco | E19: ='Complete List_09252026'!G126 -> CA | F19: ='Complete List_09252026'!H126 -> 94102 | G19: ='Complete List_09252026'!J126 -> president@hayesvalleysf.org | H19: ='Complete List_09252026'!K126 -> Electronic | I19: ='Complete List_09252026'!L126 -> Castro/Upper Market, Downtown/Civic Center, Mission, South of Market, Western Addition
A20: Hayes Valley Safe | B20: ='Complete List_09252026'!C128 -> Richard Johnson | C20: ='Complete List_09252026'!E128 -> 415 Buchanan St Apt C | D20: ='Complete List_09252026'!F128 -> San Francisco | E20: ='Complete List_09252026'!G128 -> CA | F20: ='Complete List_09252026'!H128 -> 94102 | G20: ='Complete List_09252026'!J128 -> info@hvsafe.com | H20: ='Complete List_09252026'!K128 -> Electronic | I20: ='Complete List_09252026'!L128 -> Castro/Upper Market, Downtown/Civic Center, Mission, South of Market, Western Addition
A21: Hayes Valley Small Business Association | B21: ='Complete List_09252026'!C127 -> Ramiz Y | C21: ='Complete List_09252026'!E127 -> 559 Hayes Street | D21: ='Complete List_09252026'!F127 -> San Francisco | E21: ='Complete List_09252026'!G127 -> CA | F21: ='Complete List_09252026'!H127 -> 94102 | G21: ='Complete List_09252026'!J127 -> info@hvsba.org | H21: ='Complete List_09252026'!K127 -> Electronic | I21: ='Complete List_09252026'!L127 -> Castro/Upper Market, Downtown/Civic Center, Mission, South of Market, Western Addition
A22: Mission Dolores Neighborhood Association | B22: ='Complete List_09252026'!C184 -> Peter Lewis | C22: ='Complete List_09252026'!E184 -> 72 Landers Street | D22: ='Complete List_09252026'!F184 -> San Francisco | E22: ='Complete List_09252026'!G184 -> CA | F22: ='Complete List_09252026'!H184 -> 94110 | G22: ='Complete List_09252026'!J184 -> missiondna@earthlink.net | H22: ='Complete List_09252026'!K184 -> Electronic | I22: ='Complete List_09252026'!L184 -> Castro/Upper Market, Mission
A23: Mt. Olympus Neighbors Association | B23: ='Complete List_09252026'!C192 -> Dan Slaughter | C23: ='Complete List_09252026'!E192 -> 379 Upper Terrace | D23: ='Complete List_09252026'!F192 -> San Francisco | E23: ='Complete List_09252026'!G192 -> CA | F23: ='Complete List_09252026'!H192 -> 94117 | G23: ='Complete List_09252026'!J192 -> dkslaughter@gmail.com | H23: ='Complete List_09252026'!K192 -> Electronic | I23: ='Complete List_09252026'!L192 -> Castro/Upper Market, Haight Ashbury
A24: San Francisco Land Use Coalition (SFLUC) | B24: ='Complete List_09252026'!C255 -> Gary Weiss | C24: ='Complete List_09252026'!E255 -> 78 Mars Street | D24: ='Complete List_09252026'!F255 -> San Francisco | E24: ='Complete List_09252026'!G255 -> CA | F24: ='Complete List_09252026'!H255 -> 94114 | G24: ='Complete List_09252026'!J255 -> garysfx@gmail.com | H24: ='Complete List_09252026'!K255 -> Electronic | I24: ='Complete List_09252026'!L255 -> Castro/Upper Market, Diamond Heights, Glen Park, Haight Ashbury, Mission, Noe Valley, South of Market, Twin Peaks, Upper Market, Western Addition
A25: Sharon Street Neighborhood Association | B25: ='Complete List_09252026'!C259 -> Bill Tannenbaum | C25: ='Complete List_09252026'!E259 -> 46 Sharon Street | D25: ='Complete List_09252026'!F259 -> San Francisco | E25: ='Complete List_09252026'!G259 -> CA | F25: ='Complete List_09252026'!H259 -> 94114 | G25: ='Complete List_09252026'!J259 -> Btannenbaum@arws.com | H25: ='Complete List_09252026'!K259 -> Electronic | I25: ='Complete List_09252026'!L259 -> Castro/Upper Market
A26: ='Complete List_09252026'!D53 -> Castro LGBTQ Cultural District | B26: ='Complete List_09252026'!C53 -> Jesse Sanford & Stephen Torres | C26: ='Complete List_09252026'!E53 -> 1800 Market Street | D26: ='Complete List_09252026'!F53 -> San Francisco | E26: ='Complete List_09252026'!G53 -> CA | F26: ='Complete List_09252026'!H53 -> 94102 | G26: ='Complete List_09252026'!J53 -> landuse@castrolgbtq.org | H26: ='Complete List_09252026'!K53 -> Electronic | I26: ='Complete List_09252026'!L53 -> Bernal Heights, Castro/Upper Market, Downtown/Civic Center, Mission, Noe Valley, South of Market
A27: ='Complete List_09252026'!D177 -> Mid-Market Neighbors | B27: ='Complete List_09252026'!C177 -> Chuck Obermeyer | C27: ='Complete List_09252026'!E177 -> 30 7th Street | D27: ='Complete List_09252026'!F177 -> San Francisco | E27: ='Complete List_09252026'!G177 -> CA | F27: ='Complete List_09252026'!H177 -> 94103 | G27: ='Complete List_09252026'!J177 -> chuck@midmarketneighbors.org | H27: ='Complete List_09252026'!K177 -> Electronic | I27: ='Complete List_09252026'!L177 -> Castro/Upper Market, Chinatown, Downtown/Civic Center, Financial District, Nob Hill, Potrero Hill, South of Market, Western Addition
A28: ='Complete List_09252026'!D154 -> Liberation Alliance for Economic and Social Change | B28: ='Complete List_09252026'!C154 -> Keith Pavlik | C28: ='Complete List_09252026'!E154 -> 2969 Mission Street | D28: ='Complete List_09252026'!F154 -> San Francisco | E28: ='Complete List_09252026'!G154 -> CA | F28: ='Complete List_09252026'!H154 -> 94110 | G28: ='Complete List_09252026'!J154 -> info@liberationalliance.org | H28: ='Complete List_09252026'!K154 -> Electronic | I28: ='Complete List_09252026'!L154 -> Bayview, Bernal Heights, Castro/Upper Market, Chinatown, Downtown/Civic Center, Excelsior, Mission, Nob Hill, Noe Valley, Outer Mission, Potrero Hill, South of Market, Western Addition
A29: ='Complete List_09252026'!D73 -> Corbett Heights Neighbors | B29: ='Complete List_09252026'!C73 -> Maryann Dresner | C29: ='Complete List_09252026'!E73 -> P.O. Box 14493 | D29: ='Complete List_09252026'!F73 -> San Francisco | E29: ='Complete List_09252026'!G73 -> CA | F29: ='Complete List_09252026'!H73 -> 94114 | G29: ='Complete List_09252026'!J73 -> info@corbettneighbors.com | H29: ='Complete List_09252026'!K73 -> Electronic | I29: ='Complete List_09252026'!L73 -> Castro/Upper Market, Noe Valley, West of Twin Peaks
A30: ='Complete List_09252026'!D47 -> Buena Vista Neighborhood Association | B30: ='Complete List_09252026'!C47 -> Rasheq Zarif | C30: ='Complete List_09252026'!E47 -> 1388 Haight Street #1236 | D30: ='Complete List_09252026'!F47 -> San Francisco | E30: ='Complete List_09252026'!G47 -> CA | F30: ='Complete List_09252026'!H47 -> 94117 | G30: ='Complete List_09252026'!J47 -> info@bvnasf.org | H30: ='Complete List_09252026'!K47 -> Electronic | I30: ='Complete List_09252026'!L47 -> Castro/Upper Market

Sheet Chinatown
A1: ORGANIZATION | B1: ='Complete List_09252026'!C1 -> NAME | C1: ='Complete List_09252026'!E1 -> ADDRESS | D1: ='Complete List_09252026'!F1 -> CITY | E1: ='Complete List_09252026'!G1 -> STATE | F1: ='Complete List_09252026'!H1 -> ZIP | G1: ='Complete List_09252026'!J1 -> EMAIL | H1: NOTIFICATION PREFERENCES | I1: ='Complete List_09252026'!L1 -> NEIGHBORHOOD OF INTEREST
A2: PHYSICAL NOTICES
A3: 874 Sacramento Street Tenants Association | B3: ='Complete List_09252026'!C10 -> Jeffrey Kwong | C3: ='Complete List_09252026'!E10 -> 1754 Hyde Street | D3: ='Complete List_09252026'!F10 -> San Francisco | E3: ='Complete List_09252026'!G10 -> CA | F3: ='Complete List_09252026'!H10 -> 94106 | G3: ='Complete List_09252026'!J10 -> cardinalsf@gmail.com | H3: ='Complete List_09252026'!K10 -> Physical | I3: ='Complete List_09252026'!L10 -> Chinatown, Downtown Civic Center, Financial District, Nob Hill, North Beach
A4: Chinese Chamber of Commerce | B4: ='Complete List_09252026'!C60 | C4: ='Complete List_09252026'!E60 -> 730 Sacramento Street | D4: ='Complete List_09252026'!F60 -> San Francisco | E4: ='Complete List_09252026'!G60 -> CA | F4: ='Complete List_09252026'!H60 -> 94108 | G4: ='Complete List_09252026'!J60 -> 0 | H4: ='Complete List_09252026'!K60 -> Physical | I4: ='Complete List_09252026'!L60 -> Chinatown
A5: Chinese Newcomers Service Center | B5: ='Complete List_09252026'!C61 -> George Chan | C5: ='Complete List_09252026'!E61 -> 777 Stockton Street #104 | D5: ='Complete List_09252026'!F61 -> San Francisco | E5: ='Complete List_09252026'!G61 -> CA | F5: ='Complete List_09252026'!H61 -> 94108 | G5: ='Complete List_09252026'!J61 -> georgechan@chinesenewcomers.org | H5: ='Complete List_09252026'!K61 -> Electronic | I5: ='Complete List_09252026'!L61 -> Chinatown
A6: Friends of Appleton-Wolfard Libraries | B6: ='Complete List_09252026'!C106 -> Howard Wong | C6: ='Complete List_09252026'!E106 -> 126 Varennes | D6: ='Complete List_09252026'!F106 -> San Francisco | E6: ='Complete List_09252026'!G106 -> CA | F6: ='Complete List_09252026'!H106 -> 94133 | G6: ='Complete List_09252026'!J106 -> WongAIA@aol.com | H6: ='Complete List_09252026'!K106 -> Physical | I6: ='Complete List_09252026'!L106 -> Chinatown, North Beach
A7: HERE Local 2 | B7: ='Complete List_09252026'!C129 -> Ian Lewis | C7: ='Complete List_09252026'!E129 -> 209 Golden Gate Avenue | D7: ='Complete List_09252026'!F129 -> San Francisco | E7: ='Complete List_09252026'!G129 -> CA | F7: ='Complete List_09252026'!H129 -> 94102 | G7: ='Complete List_09252026'!J129 -> 0 | H7: ='Complete List_09252026'!K129 -> Physical | I7: ='Complete List_09252026'!L129 -> Chinatown, Downtown/Civic Center, Marina, Mission, Nob Hill, North Beach, Pacific Heights, Presidio, South of Market
A8: Hotel Zeppelin | B8: ='Complete List_09252026'!C131 -> Antonio Flores | C8: ='Complete List_09252026'!E131 -> 545 Post Street | D8: ='Complete List_09252026'!F131 -> San Francisco | E8: ='Complete List_09252026'!G131 -> CA | F8: ='Complete List_09252026'!H131 -> 94102 | G8: ='Complete List_09252026'!J131 -> antonio.flores@viceroyhotelgroup.com | H8: ='Complete List_09252026'!K131 -> Physical | I8: ='Complete List_09252026'!L131 -> Castro/Upper Market, Chinatown, Downtown/Civic Center, Financial District, Nob Hill, North Beach, South of Market, Treasure Island
